<?xml version="1.0" encoding="UTF-8"?>
<!-- Generated by org.testng.reporters.JUnitReportReporter -->
<testsuite hostname="EPUALVIW00BC" failures="1" tests="3" name="test.ExampleTest" time="0.541" errors="0" timestamp="28 Feb 2023 09:32:39 GMT">
  <testcase classname="test.ExampleTest" name="passwordTest" time="0.015">
    <failure message="This assertion have to fail expected [true] but found [false]" type="java.lang.AssertionError">
      <![CDATA[java.lang.AssertionError: This assertion have to fail expected [true] but found [false]
	at org.testng.Assert.fail(Assert.java:94)
	at org.testng.Assert.failNotEquals(Assert.java:496)
	at org.testng.Assert.assertTrue(Assert.java:42)
	at test.ExampleTest.passwordTest(ExampleTest.java:20)
	at java.base/jdk.internal.reflect.NativeMethodAccessorImpl.invoke0(Native Method)
	at java.base/jdk.internal.reflect.NativeMethodAccessorImpl.invoke(NativeMethodAccessorImpl.java:77)
	at java.base/jdk.internal.reflect.DelegatingMethodAccessorImpl.invoke(DelegatingMethodAccessorImpl.java:43)
	at java.base/java.lang.reflect.Method.invoke(Method.java:568)
	at org.testng.internal.MethodInvocationHelper.invokeMethod(MethodInvocationHelper.java:85)
	at org.testng.internal.Invoker.invokeMethod(Invoker.java:639)
	at org.testng.internal.Invoker.invokeTestMethod(Invoker.java:816)
	at org.testng.internal.Invoker.invokeTestMethods(Invoker.java:1124)
	at org.testng.internal.TestMethodWorker.invokeTestMethods(TestMethodWorker.java:125)
	at org.testng.internal.TestMethodWorker.run(TestMethodWorker.java:108)
	at org.testng.TestRunner.privateRun(TestRunner.java:774)
	at org.testng.TestRunner.run(TestRunner.java:624)
	at org.testng.SuiteRunner.runTest(SuiteRunner.java:359)
	at org.testng.SuiteRunner.runSequentially(SuiteRunner.java:354)
	at org.testng.SuiteRunner.privateRun(SuiteRunner.java:312)
	at org.testng.SuiteRunner.run(SuiteRunner.java:261)
	at org.testng.SuiteRunnerWorker.runSuite(SuiteRunnerWorker.java:52)
	at org.testng.SuiteRunnerWorker.run(SuiteRunnerWorker.java:86)
	at org.testng.TestNG.runSuitesSequentially(TestNG.java:1191)
	at org.testng.TestNG.runSuitesLocally(TestNG.java:1116)
	at org.testng.TestNG.run(TestNG.java:1024)
	at org.apache.maven.surefire.testng.TestNGExecutor.run(TestNGExecutor.java:324)
	at org.apache.maven.surefire.testng.TestNGXmlTestSuite.execute(TestNGXmlTestSuite.java:74)
	at org.apache.maven.surefire.testng.TestNGProvider.invoke(TestNGProvider.java:123)
	at org.apache.maven.surefire.booter.ForkedBooter.runSuitesInProcess(ForkedBooter.java:456)
	at org.apache.maven.surefire.booter.ForkedBooter.execute(ForkedBooter.java:169)
	at org.apache.maven.surefire.booter.ForkedBooter.run(ForkedBooter.java:595)
	at org.apache.maven.surefire.booter.ForkedBooter.main(ForkedBooter.java:581)
]]>
    </failure>
  </testcase> <!-- passwordTest -->
  <testcase classname="test.ExampleTest" name="suiteNameTest" time="0.001"/>
  <testcase classname="test.ExampleTest" name="userNameTest" time="0.525"/>
</testsuite> <!-- test.ExampleTest -->
